Workbook
Name NativeTimeline_Order_Date: #N/A
Name Slicer_Category: #N/A
Name Slicer_Customer_Segment: #N/A
Name Slicer_Division: #N/A
Name Slicer_Division1: #N/A
Name Slicer_Gender: #N/A
Name Slicer_Product_Name: #N/A
Name Slicer_Sales_Channel: #N/A

Sheet Raw_Backup
A1: Customer ID | B1: Gender | C1: Region | D1: Age | E1: Product Name | F1: Category | G1: Unit Price | H1: Quantity | I1: Total Price | J1: Order Date | K1: Sales Channel
A2: CUST0268 | B2: Male | C2: North | E2: Monitor | F2: Electronics | G2: 300 | H2: 5 | I2: 1500 | J2: 45268 | K2: Online
A3: CUST0046 | B3: Male | C3: West | D3: 22 | E3: Headphones | F3: Accessories | G3: 100 | H3: 2 | I3: 200 | J3: 45025 | K3: Online
A4: CUST0169 | B4: Female | C4: South | D4: 54 | E4: Monitor | F4: Electronics | G4: 300 | H4: 1 | I4: 300 | J4: 45166 | K4: Marketplace
A5: CUST0002 | B5: Male | C5: North | D5: 23 | E5: Headphones | F5: Accessories | G5: 100 | H5: 5 | I5: 500 | J5: 44944 | K5: Retail Store
A6: CUST0173 | B6: Female | C6: South | E6: Laptop | F6: Electronics | G6: 1500 | H6: 3 | I6: 4500 | J6: 44945 | K6: Retail Store
A7: CUST0147 | B7: Male | C7: North | D7: 64 | E7: Smartwatch | F7: Wearables | G7: 200 | H7: 2 | I7: 400 | J7: 44937 | K7: Retail Store
A8: CUST0262 | B8: Male | C8: East | D8: 27 | E8: Smartwatch | F8: Wearables | G8: 200 | H8: 1 | I8: 200 | J8: 45222 | K8: Online
A9: CUST0159 | B9: Female | C9: South | D9: 18 | E9: Keyboard | F9: Accessories | G9: 50 | H9: 2 | I9: 100 | J9: 45092 | K9: Online
A10: CUST0046 | B10: Female | C10: East | D10: 22 | E10: Mouse | F10: Accessories | G10: 30 | H10: 1 | I10: 30 | J10: 44982 | K10: Corporate Sales
A11: CUST0023 | B11: Male | C11: West | D11: 29 | E11: Headphones | F11: Accessories | G11: 100 | H11: 3 | I11: 300 | J11: 45039 | K11: Online
A12: CUST0201 | B12: Female | C12: East | D12: 49 | E12: Headphones | F12: Accessories | G12: 100 | H12: 2 | I12: 200 | J12: 45078 | K12: Online
A13: CUST0283 | B13: Female | C13: West | D13: 67 | E13: Mouse | F13: Accessories | G13: 30 | H13: 3 | I13: 90 | J13: 45182 | K13: Online
A14: CUST0199 | B14: Female | C14: West | D14: 41 | E14: Keyboard | F14: Accessories | G14: 50 | H14: 5 | I14: 250 | J14: 44974 | K14: Retail Store
A15: CUST0039 | B15: Male | C15: South | D15: 60 | E15: Keyboard | F15: Accessories | G15: 50 | H15: 4 | I15: 200 | J15: 45270 | K15: Retail Store
A16: CUST0276 | B16: Male | C16: West | D16: 66 | E16: Mouse | F16: Accessories | G16: 30 | H16: 1 | I16: 30 | J16: 45106 | K16: Online
A17: CUST0143 | B17: Female | D17: 36 | E17: Smartwatch | F17: Wearables | G17: 200 | H17: 3 | I17: 600 | J17: 45121 | K17: Retail Store
A18: CUST0139 | B18: Male | C18: North | D18: 57 | E18: Laptop | F18: Electronics | G18: 1500 | H18: 4 | I18: 6000 | J18: 45059 | K18: Corporate Sales
A19: CUST0210 | B19: Male | C19: South | D19: 30 | E19: Smartphone | F19: Electronics | G19: 800 | H19: 2 | I19: 1600 | J19: 45086 | K19: Retail Store
A20: CUST0293 | B20: Female | C20: East | D20: 32 | E20: Smartwatch | F20: Wearables | G20: 200 | H20: 5 | I20: 1000 | J20: 45098 | K20: Corporate Sales
A21: CUST0049 | B21: Female | C21: West | D21: 59 | E21: Monitor | F21: Electronics | G21: 300 | H21: 4 | I21: 1200 | J21: 45256 | K21: Marketplace
A22: CUST0283 | B22: Female | C22: East | D22: 67 | E22: Smartphone | F22: Electronics | G22: 800 | H22: 5 | I22: 4000 | J22: 45238 | K22: Online
A23: CUST0196 | B23: Female | C23: South | D23: 37 | E23: Mouse | F23: Accessories | G23: 30 | H23: 3 | I23: 90 | J23: 45287 | K23: Retail Store
A24: CUST0050 | B24: Male | C24: North | E24: Mouse | F24: Accessories | G24: 30 | H24: 3 | I24: 90 | J24: 45083 | K24: Corporate Sales
A25: CUST0007 | B25: Female | C25: East | D25: 52 | E25: Headphones | F25: Accessories | G25: 100 | H25: 2 | I25: 200 | J25: 45227 | K25: Marketplace
A26: CUST0242 | B26: Male | C26: North | D26: 58 | E26: Smartphone | F26: Electronics | G26: 800 | H26: 4 | I26: 3200 | J26: 45290 | K26: Marketplace
A27: CUST0042 | B27: Female | C27: South | D27: 57 | E27: Keyboard | F27: Accessories | G27: 50 | H27: 1 | I27: 50 | J27: 45264 | K27: Retail Store
A28: CUST0264 | B28: Male | C28: East | D28: 59 | E28: Smartphone | F28: Electronics | G28: 1658.4323 | H28: 2 | I28: 1600 | J28: 44958 | K28: Retail Store
A29: CUST0053 | B29: Female | C29: North | D29: 25 | E29: Smartwatch | F29: Wearables | G29: 200 | H29: 1 | I29: 200 | J29: 45152 | K29: Marketplace
A30: CUST0154 | B30: Female | C30: East | D30: 31 | E30: Smartphone | F30: Electronics | G30: 800 | H30: 1 | I30: 800 | J30: 45267 | K30: Online
A31: CUST0190 | B31: Male | C31: North | D31: 28 | E31: Keyboard | F31: Accessories | G31: 50 | H31: 4 | I31: 200 | J31: 45105 | K31: Online
A32: CUST0038 | B32: Female | C32: East | D32: 57 | E32: Monitor | F32: Electronics | G32: 300 | H32: 2 | I32: 600 | J32: 45247 | K32: Corporate Sales
A33: CUST0288 | B33: Female | C33: South | E33: Laptop | F33: Electronics | G33: 1500 | H33: 4 | I33: 6000 | J33: 44951 | K33: Online
A34: CUST0124 | B34: Female | C34: South | D34: 53 | E34: Monitor | F34: Electronics | G34: 300 | H34: 2 | I34: 600 | J34: 45174 | K34: Marketplace
A35: CUST0298 | B35: Female | C35: South | D35: 58 | E35: Headphones | F35: Accessories | G35: 100 | H35: 5 | I35: 500 | J35: 45186 | K35: Marketplace
A36: CUST0211 | B36: Female | C36: South | D36: 35 | E36: Mouse | F36: Accessories | G36: 30 | H36: 3 | I36: 90 | J36: 45285 | K36: Marketplace
A37: CUST0060 | B37: Male | C37: North | D37: 41 | E37: Laptop | F37: Electronics | G37: 1500 | H37: 4 | I37: 6000 | J37: 44940 | K37: Online
A38: CUST0284 | B38: Female | C38: West | D38: 64 | E38: Monitor | F38: Electronics | G38: 300 | H38: 1 | I38: 300 | J38: 45139 | K38: Corporate Sales
A39: CUST0282 | B39: Male | C39: North | E39: Smartphone | F39: Electronics | G39: 800 | H39: 2 | I39: 1600 | J39: 44969 | K39: Online
A40: CUST0205 | B40: Female | C40: South | D40: 43 | E40: Monitor | F40: Electronics | G40: 300 | H40: 2 | I40: 600 | J40: 45064 | K40: Corporate Sales
...

Sheet Customer Segment Dashboard

Sheet Customer Segment Pivot Table
C4: Customer Segment | D4: Average of Spending | F4: Customer Segment | G4: Average of Frequency
C5: Champions | D5: 1857816.6 | F5: Champions | G5: 9.24
C6: At Risk | D6: 1235219.6 | F6: Loyal Customers | G6: 8.7586207
C7: Loyal Customers | D7: 1063335 | F7: At Risk | G7: 6.7179487
C8: Potential Loyal | D8: 1005886.8 | F8: Potential Loyal | G8: 5.5882353
C9: New Customers | D9: 779292.86 | F9: New Customers | G9: 4.5714286
C10: Lost/Churned | D10: 379604.59 | F10: Low Engagement | G10: 4.2222222
C11: Low Engagement | D11: 284676.67 | F11: Lost/Churned | G11: 3.7297297
C12: Grand Total | D12: 1108307.1 | F12: Grand Total | G12: 6.815331
A15: Total Revenue | C15: Total Customers | E15: Average Customer Value | G15: Average of Frequency | I15: Average of Recency | K15: Total Transactions
A16: 318084150 | C16: 287 | E16: 1108307.1 | G16: 6.815331 | I16: 105.35889 | K16: 1956
O17: Dynamic Range for Frequency vs Monetary Chart
A19: Customer Segment | B19: Total Customers | D19: Customer Segment | E19: Total Revenue | H19: Customer Segment | I19: Average of Recency | K19: Customers | L19: Sum of Frequency | M19: Sum of Monetary | O19: Customer | P19: Frequency | Q19: Monetary
A20: At Risk | B20: 78 | D20: At Risk | E20: 96347130 | H20: Lost/Churned | I20: 242.27027 | K20: CUST0204 | L20: 13 | M20: 4280400 | O20: {=_xlfn._xlws.FILTER(K20:M306,(K20:K306<>"")*(K20:K306<>"Grand Total"))} -> CUST0204 | P20: 13 | Q20: 4280400
A21: Loyal Customers | B21: 58 | D21: Champions | E21: 92890830 | H21: At Risk | I21: 188.69231 | K21: CUST0139 | L21: 12 | M21: 3954450 | O21: CUST0139 | P21: 12 | Q21: 3954450
A22: Champions | B22: 50 | D22: Loyal Customers | E22: 61673430 | H22: Low Engagement | I22: 67.222222 | K22: CUST0095 | L22: 14 | M22: 3940920 | O22: CUST0095 | P22: 14 | Q22: 3940920
A23: Lost/Churned | B23: 37 | D23: Potential Loyal | E23: 34200150 | H23: Potential Loyal | I23: 53.294118 | K23: CUST0131 | L23: 13 | M23: 3100830 | O23: CUST0131 | P23: 13 | Q23: 3100830
A24: Potential Loyal | B24: 34 | D24: New Customers | E24: 16365150 | H24: Loyal Customers | I24: 44.896552 | K24: CUST0129 | L24: 11 | M24: 3057780 | O24: CUST0129 | P24: 11 | Q24: 3057780
A25: New Customers | B25: 21 | D25: Lost/Churned | E25: 14045370 | H25: New Customers | I25: 23.333333 | K25: CUST0031 | L25: 14 | M25: 3036870 | O25: CUST0031 | P25: 14 | Q25: 3036870
A26: Low Engagement | B26: 9 | D26: Low Engagement | E26: 2562090 | H26: Champions | I26: 20.9 | K26: CUST0064 | L26: 13 | M26: 2765040 | O26: CUST0064 | P26: 13 | Q26: 2765040
A27: Grand Total | B27: 287 | D27: Grand Total | E27: 318084150 | H27: Grand Total | I27: 105.35889 | K27: CUST0173 | L27: 12 | M27: 2739210 | O27: CUST0173 | P27: 12 | Q27: 2739210
K28: CUST0218 | L28: 11 | M28: 2719530 | O28: CUST0218 | P28: 11 | Q28: 2719530
E29: Dynamic Range for Frequency vs Recency Chart | K29: CUST0088 | L29: 8 | M29: 2669100 | O29: CUST0088 | P29: 8 | Q29: 2669100
K30: CUST0200 | L30: 8 | M30: 2626050 | O30: CUST0200 | P30: 8 | Q30: 2626050
A31: Customers | B31: Sum of Frequency | C31: Sum of Recency | E31: {=_xlfn._xlws.FILTER(A31:C319,(A31:A319<>"")*(A31:A319<>"Grand Total"))} -> Customers | F31: Sum of Frequency | G31: Sum of Recency | K31: CUST0244 | L31: 8 | M31: 2607600 | O31: CUST0244 | P31: 8 | Q31: 2607600
A32: CUST0031 | B32: 14 | C32: 81 | E32: CUST0031 | F32: 14 | G32: 81 | K32: CUST0269 | L32: 8 | M32: 2521500 | O32: CUST0269 | P32: 8 | Q32: 2521500
A33: CUST0044 | B33: 14 | C33: 61 | E33: CUST0044 | F33: 14 | G33: 61 | K33: CUST0081 | L33: 9 | M33: 2392350 | O33: CUST0081 | P33: 9 | Q33: 2392350
A34: CUST0095 | B34: 14 | C34: 46 | E34: CUST0095 | F34: 14 | G34: 46 | K34: CUST0298 | L34: 10 | M34: 2303790 | O34: CUST0298 | P34: 10 | Q34: 2303790
A35: CUST0204 | B35: 13 | C35: 1 | E35: CUST0204 | F35: 13 | G35: 1 | K35: CUST0203 | L35: 10 | M35: 2303790 | O35: CUST0203 | P35: 10 | Q35: 2303790
A36: CUST0091 | B36: 13 | C36: 1 | E36: CUST0091 | F36: 13 | G36: 1 | K36: CUST0047 | L36: 10 | M36: 2301330 | O36: CUST0047 | P36: 10 | Q36: 2301330
A37: CUST0052 | B37: 13 | C37: 14 | E37: CUST0052 | F37: 13 | G37: 14 | K37: CUST0242 | L37: 7 | M37: 2287800 | O37: CUST0242 | P37: 7 | Q37: 2287800
A38: CUST0064 | B38: 13 | C38: 11 | E38: CUST0064 | F38: 13 | G38: 11 | K38: CUST0134 | L38: 8 | M38: 2273040 | O38: CUST0134 | P38: 8 | Q38: 2273040
A39: CUST0131 | B39: 13 | C39: 19 | E39: CUST0131 | F39: 13 | G39: 19 | K39: CUST0137 | L39: 11 | M39: 2250900 | O39: CUST0137 | P39: 11 | Q39: 2250900
A40: CUST0174 | B40: 12 | C40: 24 | E40: CUST0174 | F40: 12 | G40: 24 | K40: CUST0001 | L40: 5 | M40: 2247210 | O40: CUST0001 | P40: 5 | Q40: 2247210
A41: CUST0186 | B41: 12 | C41: 33 | E41: CUST0186 | F41: 12 | G41: 33 | K41: CUST0041 | L41: 5 | M41: 2201700 | O41: CUST0041 | P41: 5 | Q41: 2201700
A42: CUST0180 | B42: 12 | C42: 7 | E42: CUST0180 | F42: 12 | G42: 7 | K42: CUST0091 | L42: 13 | M42: 2200470 | O42: CUST0091 | P42: 13 | Q42: 2200470
A43: CUST0139 | B43: 12 | C43: 26 | E43: CUST0139 | F43: 12 | G43: 26 | K43: CUST0281 | L43: 8 | M43: 2195550 | O43: CUST0281 | P43: 8 | Q43: 2195550
... A306: CUST0187 | B306: 3 | C306: 83 | E306: CUST0187 | F306: 3 | G306: 83 | K306: CUST0035 | L306: 3 | M306: 45510 | O306: CUST0035 | P306: 3 | Q306: 45510
A307: CUST0286 | B307: 3 | C307: 232 | E307: CUST0286 | F307: 3 | G307: 232 | K307: Grand Total | L307: 1956 | M307: 318084150
A308: CUST0146 | B308: 3 | C308: 17 | E308: CUST0146 | F308: 3 | G308: 17
...

Sheet Customer RFM Table
A1: Customer ID | B1: Division | C1: Recency | D1: Frequency | E1: Monetary | F1: R Score | G1: F Score | H1: M Score | I1: Customer Segment | K1: Column1 | L1: Recency Percentile | M1: Frequency Percentile | N1: Monetary Percentile
A2: CUST0001 | B2: =_xlfn.XLOOKUP(A2,Cleaned_Data!$B$1:$B$1957,Cleaned_Data!$D$1:$D$1957) -> Chattogram | C2: 168 | D2: 5 | E2: 2247210 | F2: =IF(C2<=$L$2,5, IF(C2<=$L$3,4, IF(C2<=$L$4,3, IF(C2<=$L$5,2,1)))) -> 2 | G2: =IF(D2>=$M$5,5, IF(D2>=$M$4,4, IF(D2>=$M$3,3, IF(D2>=$M$2,2,1)))) -> 2 | H2: =IF(E2>=$N$5,5, IF(E2>=$N$4,4, IF(E2>=$N$3,3, IF(E2>=$N$2,2,1)))) -> 5 | I2: =IF(AND(F2>=4,G2>=4,H2>=4),"Champions", IF(AND(F2<=2,OR(G2>=3,H2>=3)),"At Risk", IF(G2>=4,"Loyal Customers", IF(AND(F2>=4,G2<=2),"New Customers", IF(AND(F2>=3,OR(G2>=3,H2>=3)),"Potential Loyal", IF(AND(F2<=2,G2<=2,H2<=2),"Lost/Churned", IF(AND(F2=3,G2<=2,H2<=2),"Low Engagement", "Unclassified"))))))) -> At Risk | K2: 20th Percentile | L2: =_xlfn.PERCENTILE.INC($C$2:$C$288, 0.2) -> 22.2 | M2: =_xlfn.PERCENTILE.INC($D$2:$D$288, 0.2) -> 5 | N2: =_xlfn.PERCENTILE.INC($E$2:$E$288, 0.2) -> 503316
A3: CUST0002 | B3: =_xlfn.XLOOKUP(A3,Cleaned_Data!$B$1:$B$1957,Cleaned_Data!$D$1:$D$1957) -> Rajshahi | C3: 43 | D3: 7 | E3: 387450 | F3: =IF(C3<=$L$2,5, IF(C3<=$L$3,4, IF(C3<=$L$4,3, IF(C3<=$L$5,2,1)))) -> 4 | G3: =IF(D3>=$M$5,5, IF(D3>=$M$4,4, IF(D3>=$M$3,3, IF(D3>=$M$2,2,1)))) -> 4 | H3: =IF(E3>=$N$5,5, IF(E3>=$N$4,4, IF(E3>=$N$3,3, IF(E3>=$N$2,2,1)))) -> 1 | I3: =IF(AND(F3>=4,G3>=4,H3>=4),"Champions", IF(AND(F3<=2,OR(G3>=3,H3>=3)),"At Risk", IF(G3>=4,"Loyal Customers", IF(AND(F3>=4,G3<=2),"New Customers", IF(AND(F3>=3,OR(G3>=3,H3>=3)),"Potential Loyal", IF(AND(F3<=2,G3<=2,H3<=2),"Lost/Churned", IF(AND(F3=3,G3<=2,H3<=2),"Low Engagement", "Unclassified"))))))) -> Loyal Customers | K3: 40th Percentile | L3: =_xlfn.PERCENTILE.INC($C$2:$C$288, 0.4) -> 47 | M3: =_xlfn.PERCENTILE.INC($D$2:$D$288, 0.4) -> 6 | N3: =_xlfn.PERCENTILE.INC($E$2:$E$288, 0.4) -> 849684
A4: CUST0003 | B4: =_xlfn.XLOOKUP(A4,Cleaned_Data!$B$1:$B$1957,Cleaned_Data!$D$1:$D$1957) -> Dhaka | C4: 157 | D4: 5 | E4: 798270 | F4: =IF(C4<=$L$2,5, IF(C4<=$L$3,4, IF(C4<=$L$4,3, IF(C4<=$L$5,2,1)))) -> 2 | G4: =IF(D4>=$M$5,5, IF(D4>=$M$4,4, IF(D4>=$M$3,3, IF(D4>=$M$2,2,1)))) -> 2 | H4: =IF(E4>=$N$5,5, IF(E4>=$N$4,4, IF(E4>=$N$3,3, IF(E4>=$N$2,2,1)))) -> 2 | I4: =IF(AND(F4>=4,G4>=4,H4>=4),"Champions", IF(AND(F4<=2,OR(G4>=3,H4>=3)),"At Risk", IF(G4>=4,"Loyal Customers", IF(AND(F4>=4,G4<=2),"New Customers", IF(AND(F4>=3,OR(G4>=3,H4>=3)),"Potential Loyal", IF(AND(F4<=2,G4<=2,H4<=2),"Lost/Churned", IF(AND(F4=3,G4<=2,H4<=2),"Low Engagement", "Unclassified"))))))) -> Lost/Churned | K4: 60th Percentile | L4: =_xlfn.PERCENTILE.INC($C$2:$C$288, 0.6) -> 99.8 | M4: =_xlfn.PERCENTILE.INC($D$2:$D$288, 0.6) -> 7 | N4: =_xlfn.PERCENTILE.INC($E$2:$E$288, 0.6) -> 1167270
A5: CUST0004 | B5: =_xlfn.XLOOKUP(A5,Cleaned_Data!$B$1:$B$1957,Cleaned_Data!$D$1:$D$1957) -> Chattogram | C5: 138 | D5: 9 | E5: 857310 | F5: =IF(C5<=$L$2,5, IF(C5<=$L$3,4, IF(C5<=$L$4,3, IF(C5<=$L$5,2,1)))) -> 2 | G5: =IF(D5>=$M$5,5, IF(D5>=$M$4,4, IF(D5>=$M$3,3, IF(D5>=$M$2,2,1)))) -> 5 | H5: =IF(E5>=$N$5,5, IF(E5>=$N$4,4, IF(E5>=$N$3,3, IF(E5>=$N$2,2,1)))) -> 3 | I5: =IF(AND(F5>=4,G5>=4,H5>=4),"Champions", IF(AND(F5<=2,OR(G5>=3,H5>=3)),"At Risk", IF(G5>=4,"Loyal Customers", IF(AND(F5>=4,G5<=2),"New Customers", IF(AND(F5>=3,OR(G5>=3,H5>=3)),"Potential Loyal", IF(AND(F5<=2,G5<=2,H5<=2),"Lost/Churned", IF(AND(F5=3,G5<=2,H5<=2),"Low Engagement", "Unclassified"))))))) -> At Risk | K5: 80th Percentile | L5: =_xlfn.PERCENTILE.INC($C$2:$C$288, 0.8) -> 174 | M5: =_xlfn.PERCENTILE.INC($D$2:$D$288, 0.8) -> 9 | N5: =_xlfn.PERCENTILE.INC($E$2:$E$288, 0.8) -> 1635900
A6: CUST0005 | B6: =_xlfn.XLOOKUP(A6,Cleaned_Data!$B$1:$B$1957,Cleaned_Data!$D$1:$D$1957) -> Rangpur | C6: 106 | D6: 5 | E6: 339480 | F6: =IF(C6<=$L$2,5, IF(C6<=$L$3,4, IF(C6<=$L$4,3, IF(C6<=$L$5,2,1)))) -> 2 | G6: =IF(D6>=$M$5,5, IF(D6>=$M$4,4, IF(D6>=$M$3,3, IF(D6>=$M$2,2,1)))) -> 2 | H6: =IF(E6>=$N$5,5, IF(E6>=$N$4,4, IF(E6>=$N$3,3, IF(E6>=$N$2,2,1)))) -> 1 | I6: =IF(AND(F6>=4,G6>=4,H6>=4),"Champions", IF(AND(F6<=2,OR(G6>=3,H6>=3)),"At Risk", IF(G6>=4,"Loyal Customers", IF(AND(F6>=4,G6<=2),"New Customers", IF(AND(F6>=3,OR(G6>=3,H6>=3)),"Potential Loyal", IF(AND(F6<=2,G6<=2,H6<=2),"Lost/Churned", IF(AND(F6=3,G6<=2,H6<=2),"Low Engagement", "Unclassified"))))))) -> Lost/Churned
A7: CUST0006 | B7: =_xlfn.XLOOKUP(A7,Cleaned_Data!$B$1:$B$1957,Cleaned_Data!$D$1:$D$1957) -> Dhaka | C7: 263 | D7: 7 | E7: 1389900 | F7: =IF(C7<=$L$2,5, IF(C7<=$L$3,4, IF(C7<=$L$4,3, IF(C7<=$L$5,2,1)))) -> 1 | G7: =IF(D7>=$M$5,5, IF(D7>=$M$4,4, IF(D7>=$M$3,3, IF(D7>=$M$2,2,1)))) -> 4 | H7: =IF(E7>=$N$5,5, IF(E7>=$N$4,4, IF(E7>=$N$3,3, IF(E7>=$N$2,2,1)))) -> 4 | I7: =IF(AND(F7>=4,G7>=4,H7>=4),"Champions", IF(AND(F7<=2,OR(G7>=3,H7>=3)),"At Risk", IF(G7>=4,"Loyal Customers", IF(AND(F7>=4,G7<=2),"New Customers", IF(AND(F7>=3,OR(G7>=3,H7>=3)),"Potential Loyal", IF(AND(F7<=2,G7<=2,H7<=2),"Lost/Churned", IF(AND(F7=3,G7<=2,H7<=2),"Low Engagement", "Unclassified"))))))) -> At Risk
A8: CUST0007 | B8: =_xlfn.XLOOKUP(A8,Cleaned_Data!$B$1:$B$1957,Cleaned_Data!$D$1:$D$1957) -> Khulna | C8: 12 | D8: 11 | E8: 1678950 | F8: =IF(C8<=$L$2,5, IF(C8<=$L$3,4, IF(C8<=$L$4,3, IF(C8<=$L$5,2,1)))) -> 5 | G8: =IF(D8>=$M$5,5, IF(D8>=$M$4,4, IF(D8>=$M$3,3, IF(D8>=$M$2,2,1)))) -> 5 | H8: =IF(E8>=$N$5,5, IF(E8>=$N$4,4, IF(E8>=$N$3,3, IF(E8>=$N$2,2,1)))) -> 5 | I8: =IF(AND(F8>=4,G8>=4,H8>=4),"Champions", IF(AND(F8<=2,OR(G8>=3,H8>=3)),"At Risk", IF(G8>=4,"Loyal Customers", IF(AND(F8>=4,G8<=2),"New Customers", IF(AND(F8>=3,OR(G8>=3,H8>=3)),"Potential Loyal", IF(AND(F8<=2,G8<=2,H8<=2),"Lost/Churned", IF(AND(F8=3,G8<=2,H8<=2),"Low Engagement", "Unclassified"))))))) -> Champions
A9: CUST0008 | B9: =_xlfn.XLOOKUP(A9,Cleaned_Data!$B$1:$B$1957,Cleaned_Data!$D$1:$D$1957) -> Barishal | C9: 140 | D9: 8 | E9: 457560 | F9: =IF(C9<=$L$2,5, IF(C9<=$L$3,4, IF(C9<=$L$4,3, IF(C9<=$L$5,2,1)))) -> 2 | G9: =IF(D9>=$M$5,5, IF(D9>=$M$4,4, IF(D9>=$M$3,3, IF(D9>=$M$2,2,1)))) -> 4 | H9: =IF(E9>=$N$5,5, IF(E9>=$N$4,4, IF(E9>=$N$3,3, IF(E9>=$N$2,2,1)))) -> 1 | I9: =IF(AND(F9>=4,G9>=4,H9>=4),"Champions", IF(AND(F9<=2,OR(G9>=3,H9>=3)),"At Risk", IF(G9>=4,"Loyal Customers", IF(AND(F9>=4,G9<=2),"New Customers", IF(AND(F9>=3,OR(G9>=3,H9>=3)),"Potential Loyal", IF(AND(F9<=2,G9<=2,H9<=2),"Lost/Churned", IF(AND(F9=3,G9<=2,H9<=2),"Low Engagement", "Unclassified"))))))) -> At Risk
A10: CUST0009 | B10: =_xlfn.XLOOKUP(A10,Cleaned_Data!$B$1:$B$1957,Cleaned_Data!$D$1:$D$1957) -> Dhaka | C10: 12 | D10: 5 | E10: 506760 | F10: =IF(C10<=$L$2,5, IF(C10<=$L$3,4, IF(C10<=$L$4,3, IF(C10<=$L$5,2,1)))) -> 5 | G10: =IF(D10>=$M$5,5, IF(D10>=$M$4,4, IF(D10>=$M$3,3, IF(D10>=$M$2,2,1)))) -> 2 | H10: =IF(E10>=$N$5,5, IF(E10>=$N$4,4, IF(E10>=$N$3,3, IF(E10>=$N$2,2,1)))) -> 2 | I10: =IF(AND(F10>=4,G10>=4,H10>=4),"Champions", IF(AND(F10<=2,OR(G10>=3,H10>=3)),"At Risk", IF(G10>=4,"Loyal Customers", IF(AND(F10>=4,G10<=2),"New Customers", IF(AND(F10>=3,OR(G10>=3,H10>=3)),"Potential Loyal", IF(AND(F10<=2,G10<=2,H10<=2),"Lost/Churned", IF(AND(F10=3,G10<=2,H10<=2),"Low Engagement", "Unclassified"))))))) -> New Customers
A11: CUST0010 | B11: =_xlfn.XLOOKUP(A11,Cleaned_Data!$B$1:$B$1957,Cleaned_Data!$D$1:$D$1957) -> Rajshahi | C11: 34 | D11: 10 | E11: 1439100 | F11: =IF(C11<=$L$2,5, IF(C11<=$L$3,4, IF(C11<=$L$4,3, IF(C11<=$L$5,2,1)))) -> 4 | G11: =IF(D11>=$M$5,5, IF(D11>=$M$4,4, IF(D11>=$M$3,3, IF(D11>=$M$2,2,1)))) -> 5 | H11: =IF(E11>=$N$5,5, IF(E11>=$N$4,4, IF(E11>=$N$3,3, IF(E11>=$N$2,2,1)))) -> 4 | I11: =IF(AND(F11>=4,G11>=4,H11>=4),"Champions", IF(AND(F11<=2,OR(G11>=3,H11>=3)),"At Risk", IF(G11>=4,"Loyal Customers", IF(AND(F11>=4,G11<=2),"New Customers", IF(AND(F11>=3,OR(G11>=3,H11>=3)),"Potential Loyal", IF(AND(F11<=2,G11<=2,H11<=2),"Lost/Churned", IF(AND(F11=3,G11<=2,H11<=2),"Low Engagement", "Unclassified"))))))) -> Champions
A12: CUST0011 | B12: =_xlfn.XLOOKUP(A12,Cleaned_Data!$B$1:$B$1957,Cleaned_Data!$D$1:$D$1957) -> Dhaka | C12: 33 | D12: 8 | E12: 931110 | F12: =IF(C12<=$L$2,5, IF(C12<=$L$3,4, IF(C12<=$L$4,3, IF(C12<=$L$5,2,1)))) -> 4 | G12: =IF(D12>=$M$5,5, IF(D12>=$M$4,4, IF(D12>=$M$3,3, IF(D12>=$M$2,2,1)))) -> 4 | H12: =IF(E12>=$N$5,5, IF(E12>=$N$4,4, IF(E12>=$N$3,3, IF(E12>=$N$2,2,1)))) -> 3 | I12: =IF(AND(F12>=4,G12>=4,H12>=4),"Champions", IF(AND(F12<=2,OR(G12>=3,H12>=3)),"At Risk", IF(G12>=4,"Loyal Customers", IF(AND(F12>=4,G12<=2),"New Customers", IF(AND(F12>=3,OR(G12>=3,H12>=3)),"Potential Loyal", IF(AND(F12<=2,G12<=2,H12<=2),"Lost/Churned", IF(AND(F12=3,G12<=2,H12<=2),"Low Engagement", "Unclassified"))))))) -> Loyal Customers
A13: CUST0012 | B13: =_xlfn.XLOOKUP(A13,Cleaned_Data!$B$1:$B$1957,Cleaned_Data!$D$1:$D$1957) -> Chattogram | C13: 103 | D13: 7 | E13: 687570 | F13: =IF(C13<=$L$2,5, IF(C13<=$L$3,4, IF(C13<=$L$4,3, IF(C13<=$L$5,2,1)))) -> 2 | G13: =IF(D13>=$M$5,5, IF(D13>=$M$4,4, IF(D13>=$M$3,3, IF(D13>=$M$2,2,1)))) -> 4 | H13: =IF(E13>=$N$5,5, IF(E13>=$N$4,4, IF(E13>=$N$3,3, IF(E13>=$N$2,2,1)))) -> 2 | I13: =IF(AND(F13>=4,G13>=4,H13>=4),"Champions", IF(AND(F13<=2,OR(G13>=3,H13>=3)),"At Risk", IF(G13>=4,"Loyal Customers", IF(AND(F13>=4,G13<=2),"New Customers", IF(AND(F13>=3,OR(G13>=3,H13>=3)),"Potential Loyal", IF(AND(F13<=2,G13<=2,H13<=2),"Lost/Churned", IF(AND(F13=3,G13<=2,H13<=2),"Low Engagement", "Unclassified"))))))) -> At Risk
A14: CUST0013 | B14: =_xlfn.XLOOKUP(A14,Cleaned_Data!$B$1:$B$1957,Cleaned_Data!$D$1:$D$1957) -> Sylhet | C14: 58 | D14: 6 | E14: 621150 | F14: =IF(C14<=$L$2,5, IF(C14<=$L$3,4, IF(C14<=$L$4,3, IF(C14<=$L$5,2,1)))) -> 3 | G14: =IF(D14>=$M$5,5, IF(D14>=$M$4,4, IF(D14>=$M$3,3, IF(D14>=$M$2,2,1)))) -> 3 | H14: =IF(E14>=$N$5,5, IF(E14>=$N$4,4, IF(E14>=$N$3,3, IF(E14>=$N$2,2,1)))) -> 2 | I14: =IF(AND(F14>=4,G14>=4,H14>=4),"Champions", IF(AND(F14<=2,OR(G14>=3,H14>=3)),"At Risk", IF(G14>=4,"Loyal Customers", IF(AND(F14>=4,G14<=2),"New Customers", IF(AND(F14>=3,OR(G14>=3,H14>=3)),"Potential Loyal", IF(AND(F14<=2,G14<=2,H14<=2),"Lost/Churned", IF(AND(F14=3,G14<=2,H14<=2),"Low Engagement", "Unclassified"))))))) -> Potential Loyal
A15: CUST0014 | B15: =_xlfn.XLOOKUP(A15,Cleaned_Data!$B$1:$B$1957,Cleaned_Data!$D$1:$D$1957) -> Dhaka | C15: 203 | D15: 5 | E15: 116850 | F15: =IF(C15<=$L$2,5, IF(C15<=$L$3,4, IF(C15<=$L$4,3, IF(C15<=$L$5,2,1)))) -> 1 | G15: =IF(D15>=$M$5,5, IF(D15>=$M$4,4, IF(D15>=$M$3,3, IF(D15>=$M$2,2,1)))) -> 2 | H15: =IF(E15>=$N$5,5, IF(E15>=$N$4,4, IF(E15>=$N$3,3, IF(E15>=$N$2,2,1)))) -> 1 | I15: =IF(AND(F15>=4,G15>=4,H15>=4),"Champions", IF(AND(F15<=2,OR(G15>=3,H15>=3)),"At Risk", IF(G15>=4,"Loyal Customers", IF(AND(F15>=4,G15<=2),"New Customers", IF(AND(F15>=3,OR(G15>=3,H15>=3)),"Potential Loyal", IF(AND(F15<=2,G15<=2,H15<=2),"Lost/Churned", IF(AND(F15=3,G15<=2,H15<=2),"Low Engagement", "Unclassified"))))))) -> Lost/Churned
A16: CUST0015 | B16: =_xlfn.XLOOKUP(A16,Cleaned_Data!$B$1:$B$1957,Cleaned_Data!$D$1:$D$1957) -> Khulna | C16: 97 | D16: 4 | E16: 1011060 | F16: =IF(C16<=$L$2,5, IF(C16<=$L$3,4, IF(C16<=$L$4,3, IF(C16<=$L$5,2,1)))) -> 3 | G16: =IF(D16>=$M$5,5, IF(D16>=$M$4,4, IF(D16>=$M$3,3, IF(D16>=$M$2,2,1)))) -> 1 | H16: =IF(E16>=$N$5,5, IF(E16>=$N$4,4, IF(E16>=$N$3,3, IF(E16>=$N$2,2,1)))) -> 3 | I16: =IF(AND(F16>=4,G16>=4,H16>=4),"Champions", IF(AND(F16<=2,OR(G16>=3,H16>=3)),"At Risk", IF(G16>=4,"Loyal Customers", IF(AND(F16>=4,G16<=2),"New Customers", IF(AND(F16>=3,OR(G16>=3,H16>=3)),"Potential Loyal", IF(AND(F16<=2,G16<=2,H16<=2),"Lost/Churned", IF(AND(F16=3,G16<=2,H16<=2),"Low Engagement", "Unclassified"))))))) -> Potential Loyal
A17: CUST0016 | B17: =_xlfn.XLOOKUP(A17,Cleaned_Data!$B$1:$B$1957,Cleaned_Data!$D$1:$D$1957) -> Mymensingh | C17: 21 | D17: 8 | E17: 1359150 | F17: =IF(C17<=$L$2,5, IF(C17<=$L$3,4, IF(C17<=$L$4,3, IF(C17<=$L$5,2,1)))) -> 5 | G17: =IF(D17>=$M$5,5, IF(D17>=$M$4,4, IF(D17>=$M$3,3, IF(D17>=$M$2,2,1)))) -> 4 | H17: =IF(E17>=$N$5,5, IF(E17>=$N$4,4, IF(E17>=$N$3,3, IF(E17>=$N$2,2,1)))) -> 4 | I17: =IF(AND(F17>=4,G17>=4,H17>=4),"Champions", IF(AND(F17<=2,OR(G17>=3,H17>=3)),"At Risk", IF(G17>=4,"Loyal Customers", IF(AND(F17>=4,G17<=2),"New Customers", IF(AND(F17>=3,OR(G17>=3,H17>=3)),"Potential Loyal", IF(AND(F17<=2,G17<=2,H17<=2),"Lost/Churned", IF(AND(F17=3,G17<=2,H17<=2),"Low Engagement", "Unclassified"))))))) -> Champions
... A288: CUST0300 | B288: =_xlfn.XLOOKUP(A288,Cleaned_Data!$B$1:$B$1957,Cleaned_Data!$D$1:$D$1957) -> Dhaka | C288: 142 | D288: 4 | E288: 503070 | F288: =IF(C288<=$L$2,5, IF(C288<=$L$3,4, IF(C288<=$L$4,3, IF(C288<=$L$5,2,1)))) -> 2 | G288: =IF(D288>=$M$5,5, IF(D288>=$M$4,4, IF(D288>=$M$3,3, IF(D288>=$M$2,2,1)))) -> 1 | H288: =IF(E288>=$N$5,5, IF(E288>=$N$4,4, IF(E288>=$N$3,3, IF(E288>=$N$2,2,1)))) -> 1 | I288: =IF(AND(F288>=4,G288>=4,H288>=4),"Champions", IF(AND(F288<=2,OR(G288>=3,H288>=3)),"At Risk", IF(G288>=4,"Loyal Customers", IF(AND(F288>=4,G288<=2),"New Customers", IF(AND(F288>=3,OR(G288>=3,H288>=3)),"Potential Loyal", IF(AND(F288<=2,G288<=2,H288<=2),"Lost/Churned", IF(AND(F288=3,G288<=2,H288<=2),"Low Engagement", "Unclassified"))))))) -> Lost/Churned
E289: =SUM(E2:E288) -> 318084150

Sheet Sales Pivot Table
A17: Sum of Total Price | C17: Count of Order ID | E17: Average of Total Price | G17: Sum of Quantity
A18: 318084150 | C18: 1956 | E18: 162619.71 | G18: 6006
A23: Month | B23: Sum of Total Price | D23: Division | E23: Sum of Total Price | G23: Product Categories | H23: Sum of Total Price | J23: Sales Channel | K23: Sum of Total Price | M23: Products | N23: Sum of Total Price
A24: Jan | B24: 29255550 | D24: Dhaka | E24: 111053010 | G24: Electronics | H24: 279037800 | J24: Corporate Sales | K24: 81779010 | M24: Mouse | N24: 3025800
A25: Feb | B25: 22682430 | D25: Chattogram | E25: 74846730 | G25: Wearables | H25: 20516400 | J25: Marketplace | K25: 81400170 | M25: Keyboard | N25: 5516550
A26: Mar | B26: 20703360 | D26: Khulna | E26: 35158320 | G26: Accessories | H26: 18529950 | J26: Online | K26: 75599490 | M26: Headphones | N26: 9987600
A27: Apr | B27: 28980030 | D27: Rajshahi | E27: 34615890 | G27: Grand Total | H27: 318084150 | J27: Retail Store | K27: 79305480 | M27: Smartwatch | N27: 20516400
A28: May | B28: 29510160 | D28: Rangpur | E28: 18122820 | J28: Grand Total | K28: 318084150 | M28: Monitor | N28: 33099300
A29: Jun | B29: 28007100 | D29: Sylhet | E29: 17862060 | M29: Smartphone | N29: 87084000
A30: Jul | B30: 21961650 | D30: Mymensingh | E30: 14635770 | M30: Laptop | N30: 158854500
A31: Aug | B31: 24644280 | D31: Barishal | E31: 11789550 | M31: Grand Total | N31: 318084150
A32: Sep | B32: 31845930 | D32: Grand Total | E32: 318084150
A33: Oct | B33: 24850920
A34: Nov | B34: 27644250
A35: Dec | B35: 27998490
A36: Grand Total | B36: 318084150
A39: Month | B39: Sum of Quantity | D39: Division | E39: Sum of Quantity
A40: Jan | B40: 580 | D40: Dhaka | E40: 2085
A41: Feb | B41: 433 | D41: Chattogram | E41: 1313
A42: Mar | B42: 442 | D42: Khulna | E42: 661
A43: Apr | B43: 487 | D43: Rajshahi | E43: 612
A44: May | B44: 510 | D44: Sylhet | E44: 420
A45: Jun | B45: 482 | D45: Rangpur | E45: 357
A46: Jul | B46: 477 | D46: Mymensingh | E46: 292
A47: Aug | B47: 469 | D47: Barishal | E47: 266
A48: Sep | B48: 547 | D48: Grand Total | E48: 6006
A49: Oct | B49: 499
A50: Nov | B50: 536
A51: Dec | B51: 544
A52: Grand Total | B52: 6006

Sheet Sales Dashboard

Sheet Cleaned_Data
A1: Order ID | B1: Customer ID | C1: Gender | D1: Division | E1: Age | F1: Sales Channel | G1: Product Name | H1: Category | I1: Unit Price | J1: Quantity | K1: Total Price | L1: Order Date | M1: Week Days | N1: Day Type
A2: ORD-00001 | B2: CUST0268 | C2: Male | D2: Dhaka | E2: 21 | F2: Online | G2: Monitor | H2: Electronics | I2: 36900 | J2: 5 | K2: =I2*J2 -> 184500 | L2: 45268 | M2: =TEXT(L2, "dddd") -> Friday | N2: =IF(OR(WEEKDAY(L2, 2)=5, WEEKDAY(L2, 2)=6), "Weekend", "Weekday") -> Weekend
A3: ORD-00002 | B3: CUST0046 | C3: Female | D3: Dhaka | E3: 22 | F3: Retail Store | G3: Headphones | H3: Accessories | I3: 12300 | J3: 2 | K3: =I3*J3 -> 24600 | L3: 45025 | M3: =TEXT(L3, "dddd") -> Sunday | N3: =IF(OR(WEEKDAY(L3, 2)=5, WEEKDAY(L3, 2)=6), "Weekend", "Weekday") -> Weekday
A4: ORD-00003 | B4: CUST0169 | C4: Female | D4: Chattogram | E4: 54 | F4: Online | G4: Monitor | H4: Electronics | I4: 36900 | J4: 1 | K4: =I4*J4 -> 36900 | L4: 45166 | M4: =TEXT(L4, "dddd") -> Monday | N4: =IF(OR(WEEKDAY(L4, 2)=5, WEEKDAY(L4, 2)=6), "Weekend", "Weekday") -> Weekday
A5: ORD-00004 | B5: CUST0002 | C5: Male | D5: Rajshahi | E5: 23 | F5: Online | G5: Headphones | H5: Accessories | I5: 12300 | J5: 5 | K5: =I5*J5 -> 61500 | L5: 44944 | M5: =TEXT(L5, "dddd") -> Wednesday | N5: =IF(OR(WEEKDAY(L5, 2)=5, WEEKDAY(L5, 2)=6), "Weekend", "Weekday") -> Weekday
A6: ORD-00005 | B6: CUST0173 | C6: Male | D6: Dhaka | E6: 65 | F6: Marketplace | G6: Laptop | H6: Electronics | I6: 184500 | J6: 3 | K6: =I6*J6 -> 553500 | L6: 44945 | M6: =TEXT(L6, "dddd") -> Thursday | N6: =IF(OR(WEEKDAY(L6, 2)=5, WEEKDAY(L6, 2)=6), "Weekend", "Weekday") -> Weekday
A7: ORD-00006 | B7: CUST0147 | C7: Male | D7: Chattogram | E7: 64 | F7: Retail Store | G7: Smartwatch | H7: Wearables | I7: 24600 | J7: 2 | K7: =I7*J7 -> 49200 | L7: 44937 | M7: =TEXT(L7, "dddd") -> Wednesday | N7: =IF(OR(WEEKDAY(L7, 2)=5, WEEKDAY(L7, 2)=6), "Weekend", "Weekday") -> Weekday
A8: ORD-00007 | B8: CUST0262 | C8: Male | D8: Mymensingh | E8: 27 | F8: Retail Store | G8: Smartwatch | H8: Wearables | I8: 24600 | J8: 1 | K8: =I8*J8 -> 24600 | L8: 45222 | M8: =TEXT(L8, "dddd") -> Monday | N8: =IF(OR(WEEKDAY(L8, 2)=5, WEEKDAY(L8, 2)=6), "Weekend", "Weekday") -> Weekday
A9: ORD-00008 | B9: CUST0159 | C9: Male | D9: Rangpur | E9: 18 | F9: Retail Store | G9: Keyboard | H9: Accessories | I9: 6150 | J9: 2 | K9: =I9*J9 -> 12300 | L9: 45092 | M9: =TEXT(L9, "dddd") -> Thursday | N9: =IF(OR(WEEKDAY(L9, 2)=5, WEEKDAY(L9, 2)=6), "Weekend", "Weekday") -> Weekday
A10: ORD-00009 | B10: CUST0046 | C10: Female | D10: Dhaka | E10: 22 | F10: Online | G10: Mouse | H10: Accessories | I10: 3690 | J10: 1 | K10: =I10*J10 -> 3690 | L10: 44982 | M10: =TEXT(L10, "dddd") -> Saturday | N10: =IF(OR(WEEKDAY(L10, 2)=5, WEEKDAY(L10, 2)=6), "Weekend", "Weekday") -> Weekend
A11: ORD-00010 | B11: CUST0023 | C11: Male | D11: Chattogram | E11: 29 | F11: Retail Store | G11: Headphones | H11: Accessories | I11: 12300 | J11: 3 | K11: =I11*J11 -> 36900 | L11: 45039 | M11: =TEXT(L11, "dddd") -> Sunday | N11: =IF(OR(WEEKDAY(L11, 2)=5, WEEKDAY(L11, 2)=6), "Weekend", "Weekday") -> Weekday
A12: ORD-00011 | B12: CUST0201 | C12: Female | D12: Chattogram | E12: 49 | F12: Retail Store | G12: Headphones | H12: Accessories | I12: 12300 | J12: 2 | K12: =I12*J12 -> 24600 | L12: 45078 | M12: =TEXT(L12, "dddd") -> Thursday | N12: =IF(OR(WEEKDAY(L12, 2)=5, WEEKDAY(L12, 2)=6), "Weekend", "Weekday") -> Weekday
A13: ORD-00012 | B13: CUST0283 | C13: Female | D13: Rajshahi | E13: 67 | F13: Retail Store | G13: Mouse | H13: Accessories | I13: 3690 | J13: 3 | K13: =I13*J13 -> 11070 | L13: 45182 | M13: =TEXT(L13, "dddd") -> Wednesday | N13: =IF(OR(WEEKDAY(L13, 2)=5, WEEKDAY(L13, 2)=6), "Weekend", "Weekday") -> Weekday
... A1957: ORD-01956 | B1957: CUST0080 | C1957: Male | D1957: Khulna | E1957: 51 | F1957: Corporate Sales | G1957: Keyboard | H1957: Accessories | I1957: 6150 | J1957: 2 | K1957: =I1957*J1957 -> 12300 | L1957: 45463 | M1957: =TEXT(L1957, "dddd") -> Thursday | N1957: =IF(OR(WEEKDAY(L1957, 2)=5, WEEKDAY(L1957, 2)=6), "Weekend", "Weekday") -> Weekday
